Workbook

Sheet Unlevered cash flow
B1: ="Discounted Cash Flow "&'[1]Income Statement'!C3 -> Discounted Cash Flow
B3: Comfortdelgro Share Price | C3: 1.48
B4: Share Price Date | C4: 46022
B6: Unlevered Free Cash Flow (UFCF) in mm
B7: Fiscal Year | C7: =YEAR(C8) -> 2024 | D7: =YEAR(D8) -> 2025 | E7: =YEAR(E8) -> 2026 | F7: =YEAR(F8) -> 2027 | G7: =YEAR(G8) -> 2028 | H7: =YEAR(H8) -> 2029 | I7: =YEAR(I8) -> 2030
B8: Fiscal Year End Date | C8: 45657 | D8: 46022 | E8: =EDATE(D8,12) -> 46387 | F8: =EDATE(E8,12) -> 46752 | G8: =EDATE(F8,12) -> 47118 | H8: =EDATE(G8,12) -> 47483 | I8: =EDATE(H8,12) -> 47848
B9: Revenue | C9: ='Profit & loss'!C12 -> 4476.5 | D9: ='Profit & loss'!D12 -> 5058.6 | E9: 5240 | F9: 5350 | G9: ='Profit & loss'!G12 -> 5457 | H9: ='Profit & loss'!H12 -> 5566.14 | I9: ='Profit & loss'!I12 -> 5683.0289
B10: Operating Expenses:
B11: Staff costs | C11: =INDEX('Income Statement - Data'!$C$3:$D$33,MATCH($B11,'Income Statement - Data'!$B$3:$B$33,0),MATCH('Profit & loss'!C$11,'Income Statement - Data'!$C$2:$D$2,0)) -> -2024.1 | D11: =INDEX('Income Statement - Data'!$C$3:$D$33,MATCH($B11,'Income Statement - Data'!$B$3:$B$33,0),MATCH('Profit & loss'!D$11,'Income Statement - Data'!$C$2:$D$2,0)) -> -2272 | E11: ='Profit & loss'!E14 -> -2353.4733 | F11: ='Profit & loss'!F14 -> -2402.8783 | G11: ='Profit & loss'!G14 -> -2450.9358 | H11: ='Profit & loss'!H14 -> -2499.9545 | I11: ='Profit & loss'!I14 -> -2552.4536
B12: Contract services and subcontractor costs | C12: =INDEX('Income Statement - Data'!$C$3:$D$33,MATCH($B12,'Income Statement - Data'!$B$3:$B$33,0),MATCH('Profit & loss'!C$11,'Income Statement - Data'!$C$2:$D$2,0)) -> -445.8 | D12: =INDEX('Income Statement - Data'!$C$3:$D$33,MATCH($B12,'Income Statement - Data'!$B$3:$B$33,0),MATCH('Profit & loss'!D$11,'Income Statement - Data'!$C$2:$D$2,0)) -> -644.3 | E12: ='Profit & loss'!E15 -> -667.40442 | F12: ='Profit & loss'!F15 -> -681.41482 | G12: ='Profit & loss'!G15 -> -695.04311 | H12: ='Profit & loss'!H15 -> -708.94398 | I12: ='Profit & loss'!I15 -> -723.8318
B13: Fuel and electricity costs | C13: =INDEX('Income Statement - Data'!$C$3:$D$33,MATCH($B13,'Income Statement - Data'!$B$3:$B$33,0),MATCH('Profit & loss'!C$11,'Income Statement - Data'!$C$2:$D$2,0)) -> -397.2 | D13: =INDEX('Income Statement - Data'!$C$3:$D$33,MATCH($B13,'Income Statement - Data'!$B$3:$B$33,0),MATCH('Profit & loss'!D$11,'Income Statement - Data'!$C$2:$D$2,0)) -> -350.9 | E13: ='Profit & loss'!E16 -> -363.48318 | F13: ='Profit & loss'!F16 -> -371.11355 | G13: ='Profit & loss'!G16 -> -378.53582 | H13: ='Profit & loss'!H16 -> -386.10654 | I13: ='Profit & loss'!I16 -> -394.21477
B14: Repairs and maintenance costs | C14: =INDEX('Income Statement - Data'!$C$3:$D$33,MATCH($B14,'Income Statement - Data'!$B$3:$B$33,0),MATCH('Profit & loss'!C$11,'Income Statement - Data'!$C$2:$D$2,0)) -> -329.7 | D14: =INDEX('Income Statement - Data'!$C$3:$D$33,MATCH($B14,'Income Statement - Data'!$B$3:$B$33,0),MATCH('Profit & loss'!D$11,'Income Statement - Data'!$C$2:$D$2,0)) -> -349.3 | E14: ='Profit & loss'!E17 -> -361.8258 | F14: ='Profit & loss'!F17 -> -369.42138 | G14: ='Profit & loss'!G17 -> -376.80981 | H14: ='Profit & loss'!H17 -> -384.34601 | I14: ='Profit & loss'!I17 -> -392.41727
B15: Materials and consumables costs | C15: =INDEX('Income Statement - Data'!$C$3:$D$33,MATCH($B15,'Income Statement - Data'!$B$3:$B$33,0),MATCH('Profit & loss'!C$11,'Income Statement - Data'!$C$2:$D$2,0)) -> -104.4 | D15: =INDEX('Income Statement - Data'!$C$3:$D$33,MATCH($B15,'Income Statement - Data'!$B$3:$B$33,0),MATCH('Profit & loss'!D$11,'Income Statement - Data'!$C$2:$D$2,0)) -> -90 | E15: ='Profit & loss'!E18 -> -93.227375 | F15: ='Profit & loss'!F18 -> -95.184438 | G15: ='Profit & loss'!G18 -> -97.088127 | H15: ='Profit & loss'!H18 -> -99.02989 | I15: ='Profit & loss'!I18 -> -101.10952
B16: Insurance premiums and accident claims | C16: =INDEX('Income Statement - Data'!$C$3:$D$33,MATCH($B16,'Income Statement - Data'!$B$3:$B$33,0),MATCH('Profit & loss'!C$11,'Income Statement - Data'!$C$2:$D$2,0)) -> -102.1 | D16: =INDEX('Income Statement - Data'!$C$3:$D$33,MATCH($B16,'Income Statement - Data'!$B$3:$B$33,0),MATCH('Profit & loss'!D$11,'Income Statement - Data'!$C$2:$D$2,0)) -> -122.6 | E16: ='Profit & loss'!E19 -> -126.9964 | F16: ='Profit & loss'!F19 -> -129.66236 | G16: ='Profit & loss'!G19 -> -132.2556 | H16: ='Profit & loss'!H19 -> -134.90072 | I16: ='Profit & loss'!I19 -> -137.73363
B17: Premises costs | C17: =INDEX('Income Statement - Data'!$C$3:$D$33,MATCH($B17,'Income Statement - Data'!$B$3:$B$33,0),MATCH('Profit & loss'!C$11,'Income Statement - Data'!$C$2:$D$2,0)) -> -86.8 | D17: =INDEX('Income Statement - Data'!$C$3:$D$33,MATCH($B17,'Income Statement - Data'!$B$3:$B$33,0),MATCH('Profit & loss'!D$11,'Income Statement - Data'!$C$2:$D$2,0)) -> -97.5 | E17: ='Profit & loss'!E20 -> -100.99632 | F17: ='Profit & loss'!F20 -> -103.11647 | G17: ='Profit & loss'!G20 -> -105.1788 | H17: ='Profit & loss'!H20 -> -107.28238 | I17: ='Profit & loss'!I20 -> -109.53531
B18: Road tax and licence fees | C18: =INDEX('Income Statement - Data'!$C$3:$D$33,MATCH($B18,'Income Statement - Data'!$B$3:$B$33,0),MATCH('Profit & loss'!C$11,'Income Statement - Data'!$C$2:$D$2,0)) -> -74.6 | D18: =INDEX('Income Statement - Data'!$C$3:$D$33,MATCH($B18,'Income Statement - Data'!$B$3:$B$33,0),MATCH('Profit & loss'!D$11,'Income Statement - Data'!$C$2:$D$2,0)) -> -85.7 | E18: ='Profit & loss'!E21 -> -88.773178 | F18: ='Profit & loss'!F21 -> -90.636737 | G18: ='Profit & loss'!G21 -> -92.449472 | H18: ='Profit & loss'!H21 -> -94.298462 | I18: ='Profit & loss'!I21 -> -96.278729
B19: Utilities,It and communication costs | C19: =INDEX('Income Statement - Data'!$C$3:$D$33,MATCH($B19,'Income Statement - Data'!$B$3:$B$33,0),MATCH('Profit & loss'!C$11,'Income Statement - Data'!$C$2:$D$2,0)) -> -73.5 | D19: =INDEX('Income Statement - Data'!$C$3:$D$33,MATCH($B19,'Income Statement - Data'!$B$3:$B$33,0),MATCH('Profit & loss'!D$11,'Income Statement - Data'!$C$2:$D$2,0)) -> -90.6 | E19: ='Profit & loss'!E22 -> -93.848891 | F19: ='Profit & loss'!F22 -> -95.819001 | G19: ='Profit & loss'!G22 -> -97.735381 | H19: ='Profit & loss'!H22 -> -99.690089 | I19: ='Profit & loss'!I22 -> -101.78358
B20: Taxi drivers’ benefits | C20: =INDEX('Income Statement - Data'!$C$3:$D$33,MATCH($B20,'Income Statement - Data'!$B$3:$B$33,0),MATCH('Profit & loss'!C$11,'Income Statement - Data'!$C$2:$D$2,0)) -> -12 | D20: =INDEX('Income Statement - Data'!$C$3:$D$33,MATCH($B20,'Income Statement - Data'!$B$3:$B$33,0),MATCH('Profit & loss'!D$11,'Income Statement - Data'!$C$2:$D$2,0)) -> -70.4 | E20: ='Profit & loss'!E23 -> -72.924525 | F20: ='Profit & loss'!F23 -> -74.455383 | G20: ='Profit & loss'!G23 -> -75.944491 | H20: ='Profit & loss'!H23 -> -77.46338 | I20: ='Profit & loss'!I23 -> -79.090111
B21: Advertising production and promotion costs | C21: =INDEX('Income Statement - Data'!$C$3:$D$33,MATCH($B21,'Income Statement - Data'!$B$3:$B$33,0),MATCH('Profit & loss'!C$11,'Income Statement - Data'!$C$2:$D$2,0)) -> -34.5 | D21: =INDEX('Income Statement - Data'!$C$3:$D$33,MATCH($B21,'Income Statement - Data'!$B$3:$B$33,0),MATCH('Profit & loss'!D$11,'Income Statement - Data'!$C$2:$D$2,0)) -> -36 | E21: ='Profit & loss'!E24 -> -37.29095 | F21: ='Profit & loss'!F24 -> -38.073775 | G21: ='Profit & loss'!G24 -> -38.835251 | H21: ='Profit & loss'!H24 -> -39.611956 | I21: ='Profit & loss'!I24 -> -40.443807
B22: Professional fees | C22: =INDEX('Income Statement - Data'!$C$3:$D$33,MATCH($B22,'Income Statement - Data'!$B$3:$B$33,0),MATCH('Profit & loss'!C$11,'Income Statement - Data'!$C$2:$D$2,0)) -> -33.2 | D22: =INDEX('Income Statement - Data'!$C$3:$D$33,MATCH($B22,'Income Statement - Data'!$B$3:$B$33,0),MATCH('Profit & loss'!D$11,'Income Statement - Data'!$C$2:$D$2,0)) -> -30.8 | E22: ='Profit & loss'!E25 -> -31.90448 | F22: ='Profit & loss'!F25 -> -32.57423 | G22: ='Profit & loss'!G25 -> -33.225715 | H22: ='Profit & loss'!H25 -> -33.890229 | I22: ='Profit & loss'!I25 -> -34.601924
... B25: Other operating costs | C25: =INDEX('Income Statement - Data'!$C$3:$D$33,MATCH($B25,'Income Statement - Data'!$B$3:$B$33,0),MATCH('Profit & loss'!C$11,'Income Statement - Data'!$C$2:$D$2,0)) -> -72.4 | D25: =INDEX('Income Statement - Data'!$C$3:$D$33,MATCH($B25,'Income Statement - Data'!$B$3:$B$33,0),MATCH('Profit & loss'!D$11,'Income Statement - Data'!$C$2:$D$2,0)) -> -69.7 | E25: ='Profit & loss'!E28 -> -72.199423 | F25: ='Profit & loss'!F28 -> -73.71506 | G25: ='Profit & loss'!G28 -> -75.189361 | H25: ='Profit & loss'!H28 -> -76.693148 | I25: ='Profit & loss'!I28 -> -78.303704
B26: EBITDA | C26: =SUM(C9:C25) -> 691.3 | D26: =SUM(D9:D25) -> 772.6 | E26: =SUM(E9:E25) -> 773.47646 | F26: =SUM(F9:F25) -> 789.71356 | G26: =SUM(G9:G25) -> 805.50783 | H26: =SUM(H9:H25) -> 821.61798 | I26: =SUM(I9:I25) -> 838.87196
B27: Depreciation and Amortization | C27: ='Profit & loss'!C32 -> -368.4 | D27: ='Profit & loss'!D32 -> -399.6 | E27: ='Profit & loss'!E32 -> -437.32044 | F27: ='Profit & loss'!F32 -> -471.88961 | G27: ='Profit & loss'!G32 -> -502.70317 | H27: ='Profit & loss'!H32 -> -530.38301 | I27: ='Profit & loss'!I32 -> -555.55293
B28: EBIT | C28: =SUM(C26:C27) -> 322.9 | D28: =SUM(D26:D27) -> 373 | E28: =SUM(E26:E27) -> 336.15601 | F28: =SUM(F26:F27) -> 317.82395 | G28: =SUM(G26:G27) -> 302.80466 | H28: =SUM(H26:H27) -> 291.23498 | I28: =SUM(I26:I27) -> 283.31904
B29: Taxation | C29: ='Profit & loss'!C40 -> -61.8 | D29: ='Profit & loss'!D40 -> -69.5 | E29: ='Profit & loss'!E40 -> -57.270983 | F29: ='Profit & loss'!F40 -> -53.712682 | G29: ='Profit & loss'!G40 -> -50.811483 | H29: ='Profit & loss'!H40 -> -48.59892 | I29: ='Profit & loss'!I40 -> -47.120317
B30: NOPAT (Net Operating Profit After Taxes) | C30: =C28*(1-WACC!$D$6) -> 258.60751 | D30: =D28*(1-WACC!$D$6) -> 298.73212 | E30: =E28*(1-WACC!$D$6) -> 269.22412 | F30: =F28*(1-WACC!$D$6) -> 254.54215 | G30: =G28*(1-WACC!$D$6) -> 242.51335 | H30: =H28*(1-WACC!$D$6) -> 233.2473 | I30: =I28*(1-WACC!$D$6) -> 226.9075
B31: (+) Depreciation & Amortization | D31: =-D27 -> 399.6 | E31: =-E27 -> 437.32044 | F31: =-F27 -> 471.88961 | G31: =-G27 -> 502.70317 | H31: =-H27 -> 530.38301 | I31: =-I27 -> 555.55293
B32: (-) Capital Expenditures | D32: =-'Fixed assets schedule'!D4 -> -583.3 | E32: =-'Fixed assets schedule'!E4 -> -604.21698 | F32: =-'Fixed assets schedule'!F4 -> -616.90092 | G32: =-'Fixed assets schedule'!G4 -> -629.23894 | H32: =-'Fixed assets schedule'!H4 -> -641.82372 | I32: =-'Fixed assets schedule'!I4 -> -655.30202
B33: (-) Change in NWC | D33: =C34-D34 -> -64.8 | E33: =D34-E34 -> -2.2304748 | F33: =E34-F34 -> -1.3525481 | G33: =F34-G34 -> -1.3156605 | H33: =G34-H34 -> -1.3419737 | I33: =H34-I34 -> -1.4372538
B34: NWC | C34: =C35-C36 -> -132.7 | D34: =D35-D36 -> -67.9 | E34: =E35-E36 -> -65.669525 | F34: =F35-F36 -> -64.316977 | G34: =G35-G36 -> -63.001317 | H34: =H35-H36 -> -61.659343 | I34: =I35-I36 -> -60.222089
B35: Current Assets | C35: ='balance sheet'!G11-'balance sheet'!G6 -> 1006.7 | D35: ='balance sheet'!H11-'balance sheet'!H6 -> 1016.4 | E35: ='balance sheet'!I11-'balance sheet'!I6 -> 1052.8478 | F35: ='balance sheet'!J11-'balance sheet'!J6 -> 1074.9496 | G35: ='balance sheet'!K11-'balance sheet'!K6 -> 1096.4486 | H35: ='balance sheet'!L11-'balance sheet'!L6 -> 1118.3776 | I35: ='balance sheet'!M11-'balance sheet'!M6 -> 1141.8635
B36: Current Liabilitites | C36: ='balance sheet'!G35-'balance sheet'!G27-'balance sheet'!G28-'balance sheet'!G29 -> 1139.4 | D36: ='balance sheet'!H35-'balance sheet'!H27-'balance sheet'!H28-'balance sheet'!H29 -> 1084.3 | E36: ='balance sheet'!I35-'balance sheet'!I27-'balance sheet'!I28-'balance sheet'!I29 -> 1118.5173 | F36: ='balance sheet'!J35-'balance sheet'!J27-'balance sheet'!J28-'balance sheet'!J29 -> 1139.2666 | G36: ='balance sheet'!K35-'balance sheet'!K27-'balance sheet'!K28-'balance sheet'!K29 -> 1159.4499 | H36: ='balance sheet'!L35-'balance sheet'!L27-'balance sheet'!L28-'balance sheet'!L29 -> 1180.0369 | I36: ='balance sheet'!M35-'balance sheet'!M27-'balance sheet'!M28-'balance sheet'!M29 -> 1202.0856
B37: Unlevered Free Cash Flow | D37: =D30+D31+D32+D33 -> 50.232121 | E37: =E30+E31+E32+E33 -> 100.09712 | F37: =F30+F31+F32+F33 -> 108.17829 | G37: =G30+G31+G32+G33 -> 114.66192 | H37: =H30+H31+H32+H33 -> 120.46461 | I37: =I30+I31+I32+I33 -> 125.72115
B41: Unlevered Free Cash Flow (UFCF) in mm
B42: Fiscal Year | C42: =YEAR(C43) -> 2024 | D42: =YEAR(D43) -> 2025 | E42: =YEAR(E43) -> 2026 | F42: =YEAR(F43) -> 2027 | G42: =YEAR(G43) -> 2028 | H42: =YEAR(H43) -> 2029 | I42: =YEAR(I43) -> 2030
B43: Fiscal Year End Date | C43: 45657 | D43: 46022 | E43: =EDATE(D43,12) -> 46387 | F43: =EDATE(E43,12) -> 46752 | G43: =EDATE(F43,12) -> 47118 | H43: =EDATE(G43,12) -> 47483 | I43: =EDATE(H43,12) -> 47848
B44: UFCF | E44: =E37 -> 100.09712 | F44: =F37 -> 108.17829 | G44: =G37 -> 114.66192 | H44: =H37 -> 120.46461 | I44: =I37 -> 125.72115
B45: Period | E45: 1 | F45: 2 | G45: 3 | H45: 4 | I45: 5
B46: PV of UFCF | E46: =E37/(1+WACC!D18)^1 -> 96.032479 | F46: =F44/(1+WACC!$D$18)^'Unlevered cash flow'!F45 -> 99.571088 | G46: =G44/(1+WACC!$D$18)^'Unlevered cash flow'!G45 -> 101.25323 | H46: =H44/(1+WACC!$D$18)^'Unlevered cash flow'!H45 -> 102.0577 | I46: =I44/(1+WACC!$D$18)^'Unlevered cash flow'!I45 -> 102.18596
B48: Sum of pv | C48: =SUM(E46:I46) -> 501.10046
...

Sheet WACC
B2: Weighted Average Cost of Capital
B4: Cost of Debt | F4: Cost of Equity
B5: Cost of debt | D5: =-'Profit & loss'!D37/('debt schedule'!C5+'debt schedule'!C11) -> 0.028987099 | F5: Risk free rate | G5: 0.028
B6: Tax Rate | D6: ='Profit & loss'!E105 -> 0.1991096 | F6: Beta | G6: ='beta calculation'!Q5 -> 0.59520093
B7: After tax cost of debt | D7: =D5*(1-D6) -> 0.023215489 | F7: Market risk premium | H7: 0.0423
F8: Cost of equity | H8: =G5+G6*H7 -> 0.053176999
B10: Capital Structure Weights
B12: Equity | D12: =2167447913*'Unlevered cash flow'!C3 -> 3.2078229e+09
B13: Debt | D13: =('debt schedule'!C5+'debt schedule'!C11)*1000000 -> 1.8215e+09
B14: total | D14: =SUM(D12:D13) -> 5.0293229e+09
B16: Equity weight | D16: =D12/D14 -> 0.63782401
B17: debt weight | D17: =D13/D14 -> 0.36217599
B18: Weighted Average Cost of Capital (WACC) | D18: =D16*H8+D17*D7 -> 0.04232566

Sheet COMPARABLE COMPANIES
A1: Company Names | B1: EV/ EBITDA
A2: Mobico Group plc | B2: =F4/F3 -> 2.8482165 | E2: Mobico Group plc
A3: FirstGroup plc | B3: =F8/F7 -> 2.3947861 | E3: EBITDA | F3: =464.8*1000000 -> 464800000
A4: kelsian group limited | B4: =F13/F12 -> 6.6296784 | E4: EV | F4: =(614086377*17.4/100)+(1249000000+346300000)-425600000+47300000 -> 1.323851e+09
A5: Average EV/ EBITDA | B5: =AVERAGE(B2:B4) -> 3.9575603
A6: Median EV/ EBITDA | B6: =MEDIAN(B2:B4) -> 2.8482165 | E6: FirstGroup plc
E7: EBITDA | F7: =702.9*1000000 -> 702900000
E8: EV | F8: =(570695015*1.662)+(447100000+710200000)-432000000+9500000 -> 1.6832951e+09
E11: kelsian group limited
E12: EBITDA | F12: =315792*1000 -> 315792000
E13: EV | F13: =(271656692*4.47)+(9838000+42313000+801903000+68873000+132694000)-176330000+3000 -> 2.0935994e+09

Sheet beta calculation
A1: STI: | I1: COMFORTDELGRO | S1: Kelsian Group | AB1: First Group plc | AK1: Mobico Group plc
A2: Date | B2: Price | C2: Open | D2: High | E2: Low | F2: Vol. | G2: returns % | I2: Date | J2: Price | K2: Open | L2: High | M2: Low | N2: Vol. | O2: returns % | P2: levered historical beta: | Q2: =SLOPE(O3:O63,G3:G63) -> 0.56673749 | S2: Date | T2: Price | U2: Open | V2: High | W2: Low | X2: Vol. | Y2: Change % | Z2: beta: | AA2: =SLOPE(Y3:Y63,G3:G63) -> 0.75171246 | AB2: Date | AC2: Price | AD2: Open | AE2: High | AF2: Low | AG2: Vol. | AH2: Change % | AI2: beta | AJ2: =SLOPE(AH3:AH63,G3:G63) -> 0.34260011 | AK2: Date | AL2: Price | AM2: Open | AN2: High | AO2: Low | AP2: Vol. | AQ2: Change % | AS2: beta | AT2: =SLOPE(AQ3:AQ63,G3:G63) -> 1.9065593
A3: 46023 | B3: 4905.13 | C3: 4652.34 | D3: 4933.88 | E3: 4648.38 | F3: 4.86B | G3: 0.0557 | I3: 46023 | J3: 1.47 | K3: 1.48 | L3: 1.49 | M3: 1.45 | N3: 152.91M | O3: -0.0068 | S3: 46023 | T3: 3.9 | U3: 4.25 | V3: 4.4 | W3: 3.86 | X3: 8.04M | Y3: -0.0824 | Z3: unlevered beta: | AA3: =AA2/(1+(1-0.2049)*(9838+42313+801903+68873+132694)/(952614)) -> 0.39961858 | AB3: 46023 | AC3: 186.4 | AD3: 190.6 | AE3: 198.3 | AF3: 180 | AG3: 34.88M | AH3: -0.022 | AI3: unlevered beta: | AJ3: =AJ2/(1+(1-0.238)*(447.1+710.2)/(719.5)) -> 0.1539319 | AK3: 46023 | AL3: 23.26 | AM3: 23.4 | AN3: 27.62 | AO3: 20.8 | AP3: 80.38M | AQ3: 0.0087 | AS3: unlevered beta: | AT3: =AT2/(1-(1-0.47759)*(1249+346.3)/(-352.3)) -> 0.56648432
A4: 45669 | B4: 4646.21 | C4: 4531.55 | D4: 4665.12 | E4: 4492.46 | F4: 4.26B | G4: 0.027 | I4: 45669 | J4: 1.48 | K4: 1.45 | L4: 1.48 | M4: 1.42 | N4: 119.00M | O4: 0.0278 | P4: median unlevered beta of comparable companies | Q4: =MEDIAN(AA3,AJ3,AT3) -> 0.39961858 | S4: 45669 | T4: 4.25 | U4: 4.65 | V4: 4.65 | W4: 4.16 | X4: 8.47M | Y4: -0.0801 | AB4: 45669 | AC4: 190.6 | AD4: 175.6 | AE4: 199.7 | AF4: 173.5 | AG4: 20.15M | AH4: 0.0787 | AK4: 45669 | AL4: 23.06 | AM4: 21.46 | AN4: 25.32 | AO4: 21 | AP4: 49.04M | AQ4: 0.0501
A5: 45668 | B5: 4523.96 | C5: 4437.38 | D5: 4575.91 | E5: 4372.64 | F5: 6.64B | G5: 0.0215 | I5: 45668 | J5: 1.44 | K5: 1.46 | L5: 1.49 | M5: 1.44 | N5: 177.74M | O5: -0.0137 | P5: relevered beta | Q5: =Q4*(1+(1-'Profit & loss'!E105)*('debt schedule'!C5+'debt schedule'!C11)/('balance sheet'!H57)) -> 0.59520093 | S5: 45668 | T5: 4.62 | U5: 4.7 | V5: 4.87 | W5: 4.35 | X5: 12.61M | Y5: -0.0513 | AB5: 45668 | AC5: 176.7 | AD5: 214 | AE5: 214 | AF5: 171.3 | AG5: 30.33M | AH5: -0.1586 | AK5: 45668 | AL5: 21.96 | AM5: 26 | AN5: 27.08 | AO5: 19 | AP5: 69.44M | AQ5: -0.1637
A6: 45667 | B6: 4428.62 | C6: 4307.76 | D6: 4478.15 | E6: 4307.76 | F6: 6.02B | G6: 0.0299 | I6: 45667 | J6: 1.46 | K6: 1.45 | L6: 1.5 | M6: 1.44 | N6: 244.31M | O6: 0.0069 | S6: 45667 | T6: 4.87 | U6: 4.81 | V6: 5.22 | W6: 4.71 | X6: 8.68M | Y6: -0.0081 | AB6: 45667 | AC6: 210 | AD6: 224.6 | AE6: 225.6 | AF6: 198.8 | AG6: 40.40M | AH6: -0.0691 | AK6: 45667 | AL6: 26.26 | AM6: 28.46 | AN6: 30.76 | AO6: 25.24 | AP6: 73.77M | AQ6: -0.0863
A7: 45666 | B7: 4300.16 | C7: 4270.86 | D7: 4375.33 | E7: 4252.27 | F7: 5.89B | G7: 0.0071 | I7: 45666 | J7: 1.45 | K7: 1.45 | L7: 1.51 | M7: 1.44 | N7: 241.76M | O7: 0 | S7: 45666 | T7: 4.91 | U7: 4.84 | V7: 5.2 | W7: 4.75 | X7: 14.48M | Y7: -0.0141 | AB7: 45666 | AC7: 225.6 | AD7: 221 | AE7: 225.6 | AF7: 210.2 | AG7: 22.11M | AH7: 0.0181 | AK7: 45666 | AL7: 28.74 | AM7: 32.98 | AN7: 33.32 | AO7: 24.36 | AP7: 125.76M | AQ7: -0.1243
A8: 45665 | B8: 4269.7 | C8: 4169.28 | D8: 4282.8 | E8: 4144.89 | F8: 5.83B | G8: 0.023 | I8: 45665 | J8: 1.45 | K8: 1.53 | L8: 1.6 | M8: 1.42 | N8: 338.76M | O8: -0.0523 | S8: 45665 | T8: 4.98 | U8: 3.73 | V8: 5.11 | W8: 3.63 | X8: 12.49M | Y8: 0.3316 | AB8: 45665 | AC8: 221.6 | AD8: 223.6 | AE8: 240.4 | AF8: 215.2 | AG8: 21.66M | AH8: -0.0125 | AK8: 45665 | AL8: 32.82 | AM8: 35.66 | AN8: 38.12 | AO8: 32.64 | AP8: 98.06M | AQ8: -0.0964
A9: 45664 | B9: 4173.77 | C9: 3972.18 | D9: 4274.32 | E9: 3968.57 | F9: 6.39B | G9: 0.0528 | I9: 45664 | J9: 1.53 | K9: 1.43 | L9: 1.64 | M9: 1.4 | N9: 379.98M | O9: 0.0699 | S9: 45664 | T9: 3.74 | U9: 3.79 | V9: 3.92 | W9: 3.68 | X9: 8.91M | Y9: -0.0132 | AB9: 45664 | AC9: 224.4 | AD9: 229.6 | AE9: 238 | AF9: 204.2 | AG9: 37.23M | AH9: -0.0269 | AK9: 45664 | AL9: 36.32 | AM9: 29.2 | AN9: 40.38 | AO9: 28 | AP9: 109.97M | AQ9: 0.2312
A10: 45663 | B10: 3964.29 | C10: 3904.42 | D10: 3971.7 | E10: 3845.78 | F10: 5.53B | G10: 0.0179 | I10: 45663 | J10: 1.43 | K10: 1.43 | L10: 1.45 | M10: 1.4 | N10: 184.35M | O10: 0.007 | S10: 45663 | T10: 3.79 | U10: 3.2 | V10: 3.88 | W10: 3.11 | X10: 24.50M | Y10: 0.1698 | AB10: 45663 | AC10: 230.6 | AD10: 191.6 | AE10: 238 | AF10: 189.7 | AG10: 41.26M | AH10: 0.2073 | AK10: 45663 | AL10: 29.5 | AM10: 30.24 | AN10: 32.74 | AO10: 25.24 | AP10: 153.28M | AQ10: -0.0134
A11: 45662 | B11: 3894.61 | C11: 3842.38 | D11: 3956.26 | E11: 3831.04 | F11: 5.68B | G11: 0.0162 | I11: 45662 | J11: 1.42 | K11: 1.53 | L11: 1.54 | M11: 1.39 | N11: 193.71M | O11: -0.0719 | S11: 45662 | T11: 3.24 | U11: 2.72 | V11: 3.35 | W11: 2.68 | X11: 19.24M | Y11: 0.1956 | AB11: 45662 | AC11: 191 | AD11: 180.8 | AE11: 194.2 | AF11: 172.1 | AG11: 26.64M | AH11: 0.106 | AK11: 45662 | AL11: 29.9 | AM11: 30.26 | AN11: 32.78 | AO11: 26.92 | AP11: 96.48M | AQ11: -0.0386
A12: 45661 | B12: 3832.51 | C12: 3950.77 | D12: 3980.28 | E12: 3372.38 | F12: 8.12B | G12: -0.0352 | I12: 45661 | J12: 1.53 | K12: 1.45 | L12: 1.55 | M12: 1.36 | N12: 247.71M | O12: 0.0479 | S12: 45661 | T12: 2.71 | U12: 2.68 | V12: 2.77 | W12: 2.19 | X12: 25.14M | Y12: 0.0112 | AB12: 45661 | AC12: 172.7 | AD12: 159.5 | AE12: 174.2 | AF12: 137.8 | AG12: 20.37M | AH12: 0.1071 | AK12: 45661 | AL12: 31.1 | AM12: 58.9 | AN12: 62.8 | AO12: 28.66 | AP12: 82.69M | AQ12: -0.4652
A13: 45660 | B13: 3972.43 | C13: 3895.37 | D13: 4005.18 | E13: 3805.7 | F13: 6.27B | G13: 0.0197 | I13: 45660 | J13: 1.46 | K13: 1.39 | L13: 1.48 | M13: 1.38 | N13: 190.45M | O13: 0.0504 | S13: 45660 | T13: 2.68 | U13: 3.11 | V13: 3.55 | W13: 2.65 | X13: 27.04M | Y13: -0.1355 | AB13: 45660 | AC13: 156 | AD13: 159.1 | AE13: 184.8 | AF13: 156 | AG13: 52.52M | AH13: -0.0232 | AK13: 45660 | AL13: 58.15 | AM13: 66.9 | AN13: 72.55 | AO13: 57 | AP13: 29.08M | AQ13: -0.1467
A14: 45659 | B14: 3895.7 | C14: 3802.42 | D14: 3951.64 | E14: 3797.83 | F14: 6.22B | G14: 0.0103 | I14: 45659 | J14: 1.39 | K14: 1.41 | L14: 1.42 | M14: 1.34 | N14: 172.73M | O14: -0.0142 | S14: 45659 | T14: 3.1 | U14: 3.76 | V14: 3.92 | W14: 2.78 | X14: 15.66M | Y14: -0.1885 | AB14: 45659 | AC14: 159.7 | AD14: 169.9 | AE14: 170 | AF14: 153.6 | AG14: 28.37M | AH14: -0.0208 | AK14: 45659 | AL14: 68.15 | AM14: 73.5 | AN14: 73.5 | AO14: 67.55 | AP14: 20.33M | AQ14: -0.0728
A15: 45658 | B15: 3855.82 | C15: 3790.36 | D15: 3886.98 | E15: 3765.41 | F15: 4.58B | G15: 0.018 | I15: 45658 | J15: 1.41 | K15: 1.48 | L15: 1.48 | M15: 1.38 | N15: 86.72M | O15: -0.0473 | S15: 45658 | T15: 3.82 | U15: 3.66 | V15: 3.84 | W15: 3.41 | X15: 10.79M | Y15: 0.0437 | AB15: 45658 | AC15: 163.1 | AD15: 162.2 | AE15: 170 | AF15: 149 | AG15: 17.42M | AH15: 0.0149 | AK15: 45658 | AL15: 73.5 | AM15: 80 | AN15: 82.2 | AO15: 71.7 | AP15: 26.10M | AQ15: -0.0731
A16: 45303 | B16: 3787.6 | C16: 3760.39 | D16: 3842.71 | E16: 3715.52 | F16: 4.57B | G16: 0.0129 | I16: 45303 | J16: 1.48 | K16: 1.46 | L16: 1.5 | M16: 1.44 | N16: 61.42M | O16: 0.0137 | S16: 45303 | T16: 3.66 | U16: 3.94 | V16: 3.99 | W16: 3.45 | X16: 11.27M | Y16: -0.0615 | AB16: 45303 | AC16: 160.7 | AD16: 158.3 | AE16: 175 | AF16: 150.2 | AG16: 22.12M | AH16: 0.0614 | AK16: 45303 | AL16: 79.3 | AM16: 87 | AN16: 90.9 | AO16: 74.85 | AP16: 42.57M | AQ16: -0.0869
A17: 45302 | B17: 3739.29 | C17: 3527.13 | D17: 3766.93 | E17: 3524.33 | F17: 7.18B | G17: 0.0507 | I17: 45302 | J17: 1.46 | K17: 1.47 | L17: 1.5 | M17: 1.45 | N17: 85.98M | O17: -0.0068 | S17: 45302 | T17: 3.9 | U17: 3.84 | V17: 3.97 | W17: 3.69 | X17: 11.53M | Y17: -0.0051 | AB17: 45302 | AC17: 151.4 | AD17: 135 | AE17: 156.5 | AF17: 128.6 | AG17: 23.20M | AH17: 0.1358 | AK17: 45302 | AL17: 86.85 | AM17: 68 | AN17: 87 | AO17: 66.75 | AP17: 27.18M | AQ17: 0.2523
... A63: 44197 | B63: 2902.52 | C63: 2846.2 | D63: 3017.15 | E63: 2832.04 | F63: 5.21B | G63: 0.0206 | I63: 44197 | J63: 1.534 | K63: 1.631 | L63: 1.699 | M63: 1.534 | N63: 209.21M | O63: -0.0539 | S63: 44197 | T63: 6.36 | U63: 6.55 | V63: 6.84 | W63: 5.81 | X63: 3.94M | Y63: -0.0359 | AB63: 44197 | AC63: 71.75 | AD63: 76.05 | AE63: 81 | AF63: 66.5 | AG63: 62.05M | AH63: -0.0304 | AK63: 44197 | AL63: 250.2 | AM63: 243 | AN63: 273.42 | AO63: 222.81 | AP63: 47.82M | AQ63: 0.0539

Sheet Profit & loss
A1: Three sheet statement model ComfortDelgro
B5: Company name | C5: ComfortDelgro
B6: ticker | C6: C52
B7: Circuit break(0=on, 1=off)
B8: Fiscal year end date | C8: 46022
C9: Base case
B10: Income statement
B11: SGD in millions | C11: 2024 | D11: 2025 | E11: =D11+1 -> 2026 | F11: =E11+1 -> 2027 | G11: =F11+1 -> 2028 | H11: =G11+1 -> 2029 | I11: =H11+1 -> 2030
B12: Net Sales | C12: =INDEX('Income Statement - Data'!$C$3:$D$33,MATCH($B12,'Income Statement - Data'!$B$3:$B$33,0),MATCH('Profit & loss'!C$11,'Income Statement - Data'!$C$2:$D$2,0)) -> 4476.5 | D12: =INDEX('Income Statement - Data'!$C$3:$D$33,MATCH($B12,'Income Statement - Data'!$B$3:$B$33,0),MATCH('Profit & loss'!D$11,'Income Statement - Data'!$C$2:$D$2,0)) -> 5058.6 | E12: 5240 | F12: 5350 | G12: =F12*(1+G48) -> 5457 | H12: =G12*(1+H48) -> 5566.14 | I12: =H12*(1+I48) -> 5683.0289
B13: Operating expenses
B14: Staff costs | C14: =INDEX('Income Statement - Data'!$C$3:$D$33,MATCH($B14,'Income Statement - Data'!$B$3:$B$33,0),MATCH('Profit & loss'!C$11,'Income Statement - Data'!$C$2:$D$2,0)) -> -2024.1 | D14: =INDEX('Income Statement - Data'!$C$3:$D$33,MATCH($B14,'Income Statement - Data'!$B$3:$B$33,0),MATCH('Profit & loss'!D$11,'Income Statement - Data'!$C$2:$D$2,0)) -> -2272 | E14: =-$E53*E$12 -> -2353.4733 | F14: =-$E53*F$12 -> -2402.8783 | G14: =-$E53*G$12 -> -2450.9358 | H14: =-$E53*H$12 -> -2499.9545 | I14: =-$E53*I$12 -> -2552.4536
B15: Contract services and subcontractor costs | C15: =INDEX('Income Statement - Data'!$C$3:$D$33,MATCH($B15,'Income Statement - Data'!$B$3:$B$33,0),MATCH('Profit & loss'!C$11,'Income Statement - Data'!$C$2:$D$2,0)) -> -445.8 | D15: =INDEX('Income Statement - Data'!$C$3:$D$33,MATCH($B15,'Income Statement - Data'!$B$3:$B$33,0),MATCH('Profit & loss'!D$11,'Income Statement - Data'!$C$2:$D$2,0)) -> -644.3 | E15: =-$E58*E$12 -> -667.40442 | F15: =-$E58*F$12 -> -681.41482 | G15: =-$E58*G$12 -> -695.04311 | H15: =-$E58*H$12 -> -708.94398 | I15: =-$E58*I$12 -> -723.8318
B16: Fuel and electricity costs | C16: =INDEX('Income Statement - Data'!$C$3:$D$33,MATCH($B16,'Income Statement - Data'!$B$3:$B$33,0),MATCH('Profit & loss'!C$11,'Income Statement - Data'!$C$2:$D$2,0)) -> -397.2 | D16: =INDEX('Income Statement - Data'!$C$3:$D$33,MATCH($B16,'Income Statement - Data'!$B$3:$B$33,0),MATCH('Profit & loss'!D$11,'Income Statement - Data'!$C$2:$D$2,0)) -> -350.9 | E16: =-$E63*E$12 -> -363.48318 | F16: =-$E63*F$12 -> -371.11355 | G16: =-$E63*G$12 -> -378.53582 | H16: =-$E63*H$12 -> -386.10654 | I16: =-$E63*I$12 -> -394.21477
B17: Repairs and maintenance costs | C17: =INDEX('Income Statement - Data'!$C$3:$D$33,MATCH($B17,'Income Statement - Data'!$B$3:$B$33,0),MATCH('Profit & loss'!C$11,'Income Statement - Data'!$C$2:$D$2,0)) -> -329.7 | D17: =INDEX('Income Statement - Data'!$C$3:$D$33,MATCH($B17,'Income Statement - Data'!$B$3:$B$33,0),MATCH('Profit & loss'!D$11,'Income Statement - Data'!$C$2:$D$2,0)) -> -349.3 | E17: =-$E68*E$12 -> -361.8258 | F17: =-$E68*F$12 -> -369.42138 | G17: =-$E68*G$12 -> -376.80981 | H17: =-$E68*H$12 -> -384.34601 | I17: =-$E68*I$12 -> -392.41727
B18: Materials and consumables costs | C18: =INDEX('Income Statement - Data'!$C$3:$D$33,MATCH($B18,'Income Statement - Data'!$B$3:$B$33,0),MATCH('Profit & loss'!C$11,'Income Statement - Data'!$C$2:$D$2,0)) -> -104.4 | D18: =INDEX('Income Statement - Data'!$C$3:$D$33,MATCH($B18,'Income Statement - Data'!$B$3:$B$33,0),MATCH('Profit & loss'!D$11,'Income Statement - Data'!$C$2:$D$2,0)) -> -90 | E18: =-$E73*E$12 -> -93.227375 | F18: =-$E73*F$12 -> -95.184438 | G18: =-$E73*G$12 -> -97.088127 | H18: =-$E73*H$12 -> -99.02989 | I18: =-$E73*I$12 -> -101.10952
B19: Insurance premiums and accident claims | C19: =INDEX('Income Statement - Data'!$C$3:$D$33,MATCH($B19,'Income Statement - Data'!$B$3:$B$33,0),MATCH('Profit & loss'!C$11,'Income Statement - Data'!$C$2:$D$2,0)) -> -102.1 | D19: =INDEX('Income Statement - Data'!$C$3:$D$33,MATCH($B19,'Income Statement - Data'!$B$3:$B$33,0),MATCH('Profit & loss'!D$11,'Income Statement - Data'!$C$2:$D$2,0)) -> -122.6 | E19: =-$E78*E$12 -> -126.9964 | F19: =-$E78*F$12 -> -129.66236 | G19: =-$E78*G$12 -> -132.2556 | H19: =-$E78*H$12 -> -134.90072 | I19: =-$E78*I$12 -> -137.73363
B20: Premises costs | C20: =INDEX('Income Statement - Data'!$C$3:$D$33,MATCH($B20,'Income Statement - Data'!$B$3:$B$33,0),MATCH('Profit & loss'!C$11,'Income Statement - Data'!$C$2:$D$2,0)) -> -86.8 | D20: =INDEX('Income Statement - Data'!$C$3:$D$33,MATCH($B20,'Income Statement - Data'!$B$3:$B$33,0),MATCH('Profit & loss'!D$11,'Income Statement - Data'!$C$2:$D$2,0)) -> -97.5 | E20: =-$E$83*E$12*($D20/SUM($D$20:$D$28)) -> -100.99632 | F20: =-$E$83*F$12*($D20/SUM($D$20:$D$28)) -> -103.11647 | G20: =-$E$83*G$12*($D20/SUM($D$20:$D$28)) -> -105.1788 | H20: =-$E$83*H$12*($D20/SUM($D$20:$D$28)) -> -107.28238 | I20: =-$E$83*I$12*($D20/SUM($D$20:$D$28)) -> -109.53531
B21: Road tax and licence fees | C21: =INDEX('Income Statement - Data'!$C$3:$D$33,MATCH($B21,'Income Statement - Data'!$B$3:$B$33,0),MATCH('Profit & loss'!C$11,'Income Statement - Data'!$C$2:$D$2,0)) -> -74.6 | D21: =INDEX('Income Statement - Data'!$C$3:$D$33,MATCH($B21,'Income Statement - Data'!$B$3:$B$33,0),MATCH('Profit & loss'!D$11,'Income Statement - Data'!$C$2:$D$2,0)) -> -85.7 | E21: =-$E$83*E$12*($D21/SUM($D$20:$D$28)) -> -88.773178 | F21: =-$E$83*F$12*($D21/SUM($D$20:$D$28)) -> -90.636737 | G21: =-$E$83*G$12*($D21/SUM($D$20:$D$28)) -> -92.449472 | H21: =-$E$83*H$12*($D21/SUM($D$20:$D$28)) -> -94.298462 | I21: =-$E$83*I$12*($D21/SUM($D$20:$D$28)) -> -96.278729
B22: Utilities,It and communication costs | C22: =INDEX('Income Statement - Data'!$C$3:$D$33,MATCH($B22,'Income Statement - Data'!$B$3:$B$33,0),MATCH('Profit & loss'!C$11,'Income Statement - Data'!$C$2:$D$2,0)) -> -73.5 | D22: =INDEX('Income Statement - Data'!$C$3:$D$33,MATCH($B22,'Income Statement - Data'!$B$3:$B$33,0),MATCH('Profit & loss'!D$11,'Income Statement - Data'!$C$2:$D$2,0)) -> -90.6 | E22: =-$E$83*E$12*($D22/SUM($D$20:$D$28)) -> -93.848891 | F22: =-$E$83*F$12*($D22/SUM($D$20:$D$28)) -> -95.819001 | G22: =-$E$83*G$12*($D22/SUM($D$20:$D$28)) -> -97.735381 | H22: =-$E$83*H$12*($D22/SUM($D$20:$D$28)) -> -99.690089 | I22: =-$E$83*I$12*($D22/SUM($D$20:$D$28)) -> -101.78358
B23: Taxi drivers’ benefits | C23: =INDEX('Income Statement - Data'!$C$3:$D$33,MATCH($B23,'Income Statement - Data'!$B$3:$B$33,0),MATCH('Profit & loss'!C$11,'Income Statement - Data'!$C$2:$D$2,0)) -> -12 | D23: =INDEX('Income Statement - Data'!$C$3:$D$33,MATCH($B23,'Income Statement - Data'!$B$3:$B$33,0),MATCH('Profit & loss'!D$11,'Income Statement - Data'!$C$2:$D$2,0)) -> -70.4 | E23: =-$E$83*E$12*($D23/SUM($D$20:$D$28)) -> -72.924525 | F23: =-$E$83*F$12*($D23/SUM($D$20:$D$28)) -> -74.455383 | G23: =-$E$83*G$12*($D23/SUM($D$20:$D$28)) -> -75.944491 | H23: =-$E$83*H$12*($D23/SUM($D$20:$D$28)) -> -77.46338 | I23: =-$E$83*I$12*($D23/SUM($D$20:$D$28)) -> -79.090111
B24: Advertising production and promotion costs | C24: =INDEX('Income Statement - Data'!$C$3:$D$33,MATCH($B24,'Income Statement - Data'!$B$3:$B$33,0),MATCH('Profit & loss'!C$11,'Income Statement - Data'!$C$2:$D$2,0)) -> -34.5 | D24: =INDEX('Income Statement - Data'!$C$3:$D$33,MATCH($B24,'Income Statement - Data'!$B$3:$B$33,0),MATCH('Profit & loss'!D$11,'Income Statement - Data'!$C$2:$D$2,0)) -> -36 | E24: =-$E$83*E$12*($D24/SUM($D$20:$D$28)) -> -37.29095 | F24: =-$E$83*F$12*($D24/SUM($D$20:$D$28)) -> -38.073775 | G24: =-$E$83*G$12*($D24/SUM($D$20:$D$28)) -> -38.835251 | H24: =-$E$83*H$12*($D24/SUM($D$20:$D$28)) -> -39.611956 | I24: =-$E$83*I$12*($D24/SUM($D$20:$D$28)) -> -40.443807
B25: Professional fees | C25: =INDEX('Income Statement - Data'!$C$3:$D$33,MATCH($B25,'Income Statement - Data'!$B$3:$B$33,0),MATCH('Profit & loss'!C$11,'Income Statement - Data'!$C$2:$D$2,0)) -> -33.2 | D25: =INDEX('Income Statement - Data'!$C$3:$D$33,MATCH($B25,'Income Statement - Data'!$B$3:$B$33,0),MATCH('Profit & loss'!D$11,'Income Statement - Data'!$C$2:$D$2,0)) -> -30.8 | E25: =-$E$83*E$12*($D25/SUM($D$20:$D$28)) -> -31.90448 | F25: =-$E$83*F$12*($D25/SUM($D$20:$D$28)) -> -32.57423 | G25: =-$E$83*G$12*($D25/SUM($D$20:$D$28)) -> -33.225715 | H25: =-$E$83*H$12*($D25/SUM($D$20:$D$28)) -> -33.890229 | I25: =-$E$83*I$12*($D25/SUM($D$20:$D$28)) -> -34.601924
B26: Impairment of good will | C26: =INDEX('Income Statement - Data'!$C$3:$D$33,MATCH($B26,'Income Statement - Data'!$B$3:$B$33,0),MATCH('Profit & loss'!C$11,'Income Statement - Data'!$C$2:$D$2,0)) -> – | D26: =INDEX('Income Statement - Data'!$C$3:$D$33,MATCH($B26,'Income Statement - Data'!$B$3:$B$33,0),MATCH('Profit & loss'!D$11,'Income Statement - Data'!$C$2:$D$2,0)) -> -2.1 | E26: =-$E$83*E$12*($D26/SUM($D$20:$D$28)) -> -2.1753054 | F26: =-$E$83*F$12*($D26/SUM($D$20:$D$28)) -> -2.2209702 | G26: =-$E$83*G$12*($D26/SUM($D$20:$D$28)) -> -2.2653896 | H26: =-$E$83*H$12*($D26/SUM($D$20:$D$28)) -> -2.3106974 | I26: =-$E$83*I$12*($D26/SUM($D$20:$D$28)) -> -2.3592221
B27: Net gain on disposal of vehicles,premises and equipment | C27: =INDEX('Income Statement - Data'!$C$3:$D$33,MATCH($B27,'Income Statement - Data'!$B$3:$B$33,0),MATCH('Profit & loss'!C$11,'Income Statement - Data'!$C$2:$D$2,0)) -> 5.1 | D27: =INDEX('Income Statement - Data'!$C$3:$D$33,MATCH($B27,'Income Statement - Data'!$B$3:$B$33,0),MATCH('Profit & loss'!D$11,'Income Statement - Data'!$C$2:$D$2,0)) -> 25.9 | E27: 0 | F27: 0 | G27: 0 | H27: 0 | I27: 0
B28: Other operating costs | C28: =INDEX('Income Statement - Data'!$C$3:$D$33,MATCH($B28,'Income Statement - Data'!$B$3:$B$33,0),MATCH('Profit & loss'!C$11,'Income Statement - Data'!$C$2:$D$2,0)) -> -72.4 | D28: =INDEX('Income Statement - Data'!$C$3:$D$33,MATCH($B28,'Income Statement - Data'!$B$3:$B$33,0),MATCH('Profit & loss'!D$11,'Income Statement - Data'!$C$2:$D$2,0)) -> -69.7 | E28: =-$E$83*E$12*($D28/SUM($D$20:$D$28)) -> -72.199423 | F28: =-$E$83*F$12*($D28/SUM($D$20:$D$28)) -> -73.71506 | G28: =-$E$83*G$12*($D28/SUM($D$20:$D$28)) -> -75.189361 | H28: =-$E$83*H$12*($D28/SUM($D$20:$D$28)) -> -76.693148 | I28: =-$E$83*I$12*($D28/SUM($D$20:$D$28)) -> -78.303704
B29: Total operating costs | C29: =SUM(C14:C28) -> -3785.2 | D29: =SUM(D14:D28) -> -4286 | E29: =SUM(E14:E28) -> -4466.5235 | F29: =SUM(F14:F28) -> -4560.2864 | G29: =SUM(G14:G28) -> -4651.4922 | H29: =SUM(H14:H28) -> -4744.522 | I29: =SUM(I14:I28) -> -4844.157
B31: EBITDA | C31: =SUM(C12:C28) -> 691.3 | D31: =SUM(D12:D28) -> 772.6 | E31: =SUM(E12:E28) -> 773.47646 | F31: =SUM(F12:F28) -> 789.71356 | G31: =SUM(G12:G28) -> 805.50783 | H31: =SUM(H12:H28) -> 821.61798 | I31: =SUM(I12:I28) -> 838.87196
B32: Depreciation and amortisation | C32: =INDEX('Income Statement - Data'!$C$3:$D$33,MATCH($B32,'Income Statement - Data'!$B$3:$B$33,0),MATCH('Profit & loss'!C$11,'Income Statement - Data'!$C$2:$D$2,0)) -> -368.4 | D32: =INDEX('Income Statement - Data'!$C$3:$D$33,MATCH($B32,'Income Statement - Data'!$B$3:$B$33,0),MATCH('Profit & loss'!D$11,'Income Statement - Data'!$C$2:$D$2,0)) -> -399.6 | E32: ='Fixed assets schedule'!E14 -> -437.32044 | F32: ='Fixed assets schedule'!F14 -> -471.88961 | G32: ='Fixed assets schedule'!G14 -> -502.70317 | H32: ='Fixed assets schedule'!H14 -> -530.38301 | I32: ='Fixed assets schedule'!I14 -> -555.55293
B34: EBIT | C34: =SUM(C31:C32) -> 322.9 | D34: =SUM(D31:D32) -> 373 | E34: =SUM(E31:E32) -> 336.15601 | F34: =SUM(F31:F32) -> 317.82395 | G34: =SUM(G31:G32) -> 302.80466 | H34: =SUM(H31:H32) -> 291.23498 | I34: =SUM(I31:I32) -> 283.31904
B35: Other income/(costs)
B36: Investments income | C36: =INDEX('Income Statement - Data'!$C$3:$D$33,MATCH($B36,'Income Statement - Data'!$B$3:$B$33,0),MATCH('Profit & loss'!C$11,'Income Statement - Data'!$C$2:$D$2,0)) -> 31.7 | D36: =INDEX('Income Statement - Data'!$C$3:$D$33,MATCH($B36,'Income Statement - Data'!$B$3:$B$33,0),MATCH('Profit & loss'!D$11,'Income Statement - Data'!$C$2:$D$2,0)) -> 20.4 | E36: =E91*E$12 -> 21.131538 | F36: =F91*F$12 -> 21.575139 | G36: =G91*G$12 -> 22.006642 | H36: =H91*H$12 -> 22.446775 | I36: =I91*I$12 -> 22.918157
B37: Finance costs | C37: =INDEX('Income Statement - Data'!$C$3:$D$33,MATCH($B37,'Income Statement - Data'!$B$3:$B$33,0),MATCH('Profit & loss'!C$11,'Income Statement - Data'!$C$2:$D$2,0)) -> -38.9 | D37: =INDEX('Income Statement - Data'!$C$3:$D$33,MATCH($B37,'Income Statement - Data'!$B$3:$B$33,0),MATCH('Profit & loss'!D$11,'Income Statement - Data'!$C$2:$D$2,0)) -> -52.8 | E37: =-('debt schedule'!D7+'debt schedule'!D13) -> -70.480763 | F37: =-('debt schedule'!E7+'debt schedule'!E13) -> -70.480763 | G37: =-('debt schedule'!F7+'debt schedule'!F13) -> -70.480763 | H37: =-('debt schedule'!G7+'debt schedule'!G13) -> -70.480763 | I37: =-('debt schedule'!H7+'debt schedule'!H13) -> -70.480763
B38: Share of results of associates and joint ventures | C38: =INDEX('Income Statement - Data'!$C$3:$D$33,MATCH($B38,'Income Statement - Data'!$B$3:$B$33,0),MATCH('Profit & loss'!C$11,'Income Statement - Data'!$C$2:$D$2,0)) -> 1.8 | D38: =INDEX('Income Statement - Data'!$C$3:$D$33,MATCH($B38,'Income Statement - Data'!$B$3:$B$33,0),MATCH('Profit & loss'!D$11,'Income Statement - Data'!$C$2:$D$2,0)) -> 0.8 | E38: =E101*E$12 -> 0.82868778 | F38: =F101*F$12 -> 0.8460839 | G38: =G101*G$12 -> 0.86300557 | H38: =H101*H$12 -> 0.88026569 | I38: =I101*I$12 -> 0.89875127
B39: EBT | C39: =SUM(C34,C36:C38) -> 317.5 | D39: =SUM(D34,D36:D38) -> 341.4 | E39: =SUM(E34,E36:E38) -> 287.63547 | F39: =SUM(F34,F36:F38) -> 269.76441 | G39: =SUM(G34,G36:G38) -> 255.19354 | H39: =SUM(H34,H36:H38) -> 244.08125 | I39: =SUM(I34,I36:I38) -> 236.65518
B40: Taxation | C40: =INDEX('Income Statement - Data'!$C$3:$D$33,MATCH($B40,'Income Statement - Data'!$B$3:$B$33,0),MATCH('Profit & loss'!C$11,'Income Statement - Data'!$C$2:$D$2,0)) -> -61.8 | D40: =INDEX('Income Statement - Data'!$C$3:$D$33,MATCH($B40,'Income Statement - Data'!$B$3:$B$33,0),MATCH('Profit & loss'!D$11,'Income Statement - Data'!$C$2:$D$2,0)) -> -69.5 | E40: =-E39*E105 -> -57.270983 | F40: =-F39*F105 -> -53.712682 | G40: =-G39*G105 -> -50.811483 | H40: =-H39*H105 -> -48.59892 | I40: =-I39*I105 -> -47.120317
B41: Net income | C41: =SUM(C39:C40) -> 255.7 | D41: =SUM(D39:D40) -> 271.9 | E41: =SUM(E39:E40) -> 230.36449 | F41: =SUM(F39:F40) -> 216.05173 | G41: =SUM(G39:G40) -> 204.38206 | H41: =SUM(H39:H40) -> 195.48233 | I41: =SUM(I39:I40) -> 189.53486
B44: Scenario assumptions | C44: 2024 | D44: =D11 -> 2025 | E44: =E11 -> 2026 | F44: =F11 -> 2027 | G44: =G11 -> 2028 | H44: =H11 -> 2029 | I44: =I11 -> 2030 | J44: Base case
B45: Revenue growth | J45: variance
B46: selected case | D46: =OFFSET(D46,MATCH($C$9,$B47:$B49,0),) -> 0.13003463 | E46: =OFFSET(E46,MATCH($C$9,$B47:$B49,0),) -> 0.035859724 | F46: =OFFSET(F46,MATCH($C$9,$B47:$B49,0),) -> 0.020992366 | G46: =OFFSET(G46,MATCH($C$9,$B47:$B49,0),) -> 0.02 | H46: =OFFSET(H46,MATCH($C$9,$B47:$B49,0),) -> 0.02 | I46: =OFFSET(I46,MATCH($C$9,$B47:$B49,0),) -> 0.021
B47: Best case | D47: =(D$12-C$12)/C$12 -> 0.13003463 | E47: =E48+$J47 -> 0.045859724 | F47: =F48+$J47 -> 0.030992366 | G47: =G48+$J47 -> 0.03 | H47: =H48+$J47 -> 0.03 | I47: =I48+$J47 -> 0.031 | J47: 0.01
...

Sheet cash Flow
B2: Cash Flow Statement | E2: Forecast
B3: $ in millions | C3: 2024 | D3: =C3+1 -> 2025 | E3: =D3+1 -> 2026 | F3: =E3+1 -> 2027 | G3: =F3+1 -> 2028 | H3: =G3+1 -> 2029 | I3: =H3+1 -> 2030
B4: Profit before Taxation | C4: 317.5 | D4: 341.4 | E4: ='Profit & loss'!E39 -> 287.63547 | F4: ='Profit & loss'!F39 -> 269.76441 | G4: ='Profit & loss'!G39 -> 255.19354 | H4: ='Profit & loss'!H39 -> 244.08125 | I4: ='Profit & loss'!I39 -> 236.65518
B5: Depreciation and amortisation | C5: 368.4 | D5: 399.6 | E5: =-'Profit & loss'!E32 -> 437.32044 | F5: =-'Profit & loss'!F32 -> 471.88961 | G5: =-'Profit & loss'!G32 -> 502.70317 | H5: =-'Profit & loss'!H32 -> 530.38301 | I5: =-'Profit & loss'!I32 -> 555.55293
B6: Finance costs | C6: 38.9 | D6: 52.8 | E6: =-'Profit & loss'!E37 -> 70.480763 | F6: =-'Profit & loss'!F37 -> 70.480763 | G6: =-'Profit & loss'!G37 -> 70.480763 | H6: =-'Profit & loss'!H37 -> 70.480763 | I6: =-'Profit & loss'!I37 -> 70.480763
B7: Dividend income | C7: -6.1 | D7: 0 | E7: 0 | F7: 0 | G7: 0 | H7: 0 | I7: 0
B8: Interest income | C8: -25.1 | D8: -18.9 | G8: 0 | H8: 0 | I8: 0
B9: Net gain on disposal of vehicles,premises and equipment | C9: -5.1 | D9: -0.3 | E9: 0 | F9: 0 | G9: 0 | H9: 0 | I9: 0
B10: Net gain on disposal of assets held for sale | C10: – | D10: -25.6 | E10: 0 | F10: 0 | G10: 0 | H10: 0 | I10: 0
B11: Net gain on disposal of subsidiaries | C11: – | D11: -1.1 | E11: 0 | F11: 0 | G11: 0 | H11: 0 | I11: 0
B12: Net gain on disposal of investments | C12: -0.4 | D12: – | E12: 0 | F12: 0 | G12: 0 | H12: 0 | I12: 0
B13: Impairment of goodwill | C13: – | D13: 2.1 | E13: 0 | F13: 0 | G13: 0 | H13: 0 | I13: 0
B14: Provision for accident claims | C14: 10.6 | D14: 33.4 | E14: =-E23 -> 28.7 | F14: =-F23 -> 21.3 | G14: =-G23 -> 21.3 | H14: =-H23 -> 21.3 | I14: =-I23 -> 21.3
B15: Allowance for inventory obsolescence | C15: 7.8 | D15: 6.1 | E15: 0 | F15: 0 | G15: 0 | H15: 0 | I15: 0
B16: Allowance for/(reversal of) expected credit losses | C16: -0.7 | D16: 0.4 | E16: 0 | F16: 0 | G16: 0 | H16: 0 | I16: 0
B17: ="change in " & "Inventories" -> change in Inventories | C17: -22 | D17: 0.8 | E17: =-('balance sheet'!I9-'balance sheet'!H9) -> -5.4255762 | F17: =-('balance sheet'!J9-'balance sheet'!I9) -> -3.2900407 | G17: =-('balance sheet'!K9-'balance sheet'!J9) -> -3.2003123 | H17: =-('balance sheet'!L9-'balance sheet'!K9) -> -3.2643186 | I17: =-('balance sheet'!M9-'balance sheet'!L9) -> -3.4960852
B18: ="change in " & "Trade, other receivables and prepayments" -> change in Trade, other receivables and prepayments | C18: -34.9 | D18: -48.3 | E18: =-(SUM('balance sheet'!I7,'balance sheet'!I8)-SUM('balance sheet'!H7,'balance sheet'!H8)) -> -31.022247 | F18: =-(SUM('balance sheet'!J7,'balance sheet'!J8)-SUM('balance sheet'!I7,'balance sheet'!I8)) -> -18.811727 | G18: =-(SUM('balance sheet'!K7,'balance sheet'!K8)-SUM('balance sheet'!J7,'balance sheet'!J8)) -> -18.298679 | H18: =-(SUM('balance sheet'!L7,'balance sheet'!L8)-SUM('balance sheet'!K7,'balance sheet'!K8)) -> -18.664653 | I18: =-(SUM('balance sheet'!M7,'balance sheet'!M8)-SUM('balance sheet'!L7,'balance sheet'!L8)) -> -19.989843
B19: ="change in " & "Service concession receivables,net of deferred grants" -> change in Service concession receivables,net of deferred grants | C19: 0.1 | D19: -133.6 | E19: 0 | F19: 0 | G19: 0 | H19: 0 | I19: 0
B20: ="change in " & "Trade and other payables" -> change in Trade and other payables | C20: 4.2 | D20: -76.9 | E20: ='balance sheet'!I30-'balance sheet'!H30 -> 34.217349 | F20: ='balance sheet'!J30-'balance sheet'!I30 -> 20.749219 | G20: ='balance sheet'!K30-'balance sheet'!J30 -> 20.183331 | H20: ='balance sheet'!L30-'balance sheet'!K30 -> 20.586998 | I20: ='balance sheet'!M30-'balance sheet'!L30 -> 22.048675
B21: ="change in " & "Other liabilities" -> change in Other liabilities | C21: -12.9 | D21: 31.6 | E21: ='balance sheet'!I43-'balance sheet'!H43 -> 0 | F21: ='balance sheet'!J43-'balance sheet'!I43 -> 0 | G21: ='balance sheet'!K43-'balance sheet'!J43 -> 0 | H21: ='balance sheet'!L43-'balance sheet'!K43 -> 0 | I21: ='balance sheet'!M43-'balance sheet'!L43 -> 0
B22: Payments of service benefits and long service awards | C22: -1.6 | D22: -1 | E22: -1 | F22: -1 | G22: -1 | H22: -1 | I22: -1
B23: Payments of accident claims | C23: -19.5 | D23: -28.7 | E23: -28.7 | F23: -21.3 | G23: -21.3 | H23: -21.3 | I23: -21.3
B24: Income tax paid | C24: -65.9 | D24: -73.8 | E24: ='Profit & loss'!E40 -> -57.270983 | F24: ='Profit & loss'!F40 -> -53.712682 | G24: ='Profit & loss'!G40 -> -50.811483 | H24: ='Profit & loss'!H40 -> -48.59892 | I24: ='Profit & loss'!I40 -> -47.120317
B25: Interest paid arising from leases | C25: -6.9 | D25: -10 | E25: =-'debt schedule'!D13 -> -10.592967 | F25: =-'debt schedule'!E13 -> -10.592967 | G25: =-'debt schedule'!F13 -> -10.592967 | H25: =-'debt schedule'!G13 -> -10.592967 | I25: =-'debt schedule'!H13 -> -10.592967
B26: Others | C26: 0.7 | D26: 1.7 | E26: 0 | F26: 0 | G26: 0 | H26: 0 | I26: 0
B27: Operating Cash Flow | C27: =SUM(C4:C26) -> 547.1 | D27: =SUM(D4:D26) -> 451.7 | E27: =SUM(E4:E26) -> 724.34226 | F27: =SUM(F4:F26) -> 745.47658 | G27: =SUM(G4:G26) -> 764.65737 | H27: =SUM(H4:H26) -> 783.41117 | I27: =SUM(I4:I26) -> 802.53833
B29: Purchases of vehicles, premises and equipment | C29: -445.1 | D29: -565.4 | E29: 0 | F29: 0 | G29: 0 | H29: 0 | I29: 0
B30: Less: Proceeds from disposal of vehicles, premises and equipment | C30: 72.1 | D30: 55.1 | E30: 0 | F30: 0 | G30: 0 | H30: 0 | I30: 0
B31: Cash payments on purchase of vehicles, premises and equipment | C31: -373 | D31: -510.3 | E31: 0 | F31: 0 | G31: 0 | H31: 0 | I31: 0
B32: Proceeds from disposal of asset held for sale | C32: – | D32: 54.5 | E32: 0 | F32: 0 | G32: 0 | H32: 0 | I32: 0
B33: Proceeds from disposal of subsidiaries | C33: – | D33: 4.7 | E33: 0 | F33: 0 | G33: 0 | H33: 0 | I33: 0
B34: Proceeds from disposal of investments | C34: – | D34: 3.2 | E34: 0 | F34: 0 | G34: 0 | H34: 0 | I34: 0
B35: Investments made | C35: -0.4 | D35: -2 | E35: 0 | F35: 0 | G35: 0 | H35: 0 | I35: 0
B36: Additions to intangible assets | C36: -23.9 | D36: -22.4 | E36: 0 | F36: 0 | G36: 0 | H36: 0 | I36: 0
B37: Acquisition of business/ subsidiaries, net of cash | C37: -604.5 | D37: -49 | E37: 0 | F37: 0 | G37: 0 | H37: 0 | I37: 0
B38: Increase in investment in associates and joint ventures | C38: -0.7 | D38: -0.8 | E38: 0 | F38: 0 | G38: 0 | H38: 0 | I38: 0
B39: Interest received | C39: 24.9 | D39: 19.5 | E39: 0 | F39: 0 | G39: 0 | H39: 0 | I39: 0
B40: Dividend received from associate/ investments | C40: 7.5 | D40: 0.1 | E40: 0 | F40: 0 | G40: 0 | H40: 0 | I40: 0
B41: capital expenditures | E41: =-'Fixed assets schedule'!E4 -> -604.21698 | F41: =-'Fixed assets schedule'!F4 -> -616.90092 | G41: =-'Fixed assets schedule'!G4 -> -629.23894 | H41: =-'Fixed assets schedule'!H4 -> -641.82372 | I41: =-'Fixed assets schedule'!I4 -> -655.30202
B43: Investing Cash Flow | C43: =SUM(C31:C42) -> -970.1 | D43: =SUM(D31:D42) -> -502.5 | E43: =SUM(E31:E42) -> -604.21698 | F43: =SUM(F31:F42) -> -616.90092 | G43: =SUM(G31:G42) -> -629.23894 | H43: =SUM(H31:H42) -> -641.82372 | I43: =SUM(I31:I42) -> -655.30202
...

Sheet balance sheet
B3: Balance Sheet
B4: SGD in million | G4: 2024 | H4: 2025 | I4: =H4+1 -> 2026 | J4: =I4+1 -> 2027 | K4: =J4+1 -> 2028 | L4: =K4+1 -> 2029 | M4: =L4+1 -> 2030
B5: Current assets:
B6: Short-term deposits and bank balances | G6: =INDEX('Balance Sheet - Data'!$C$3:$D$57,MATCH('balance sheet'!$B6,'Balance Sheet - Data'!$B$3:$B$57,0),MATCH('balance sheet'!G$4,'Balance Sheet - Data'!$C$2:$D$2,0)) -> 892.4 | H6: =INDEX('Balance Sheet - Data'!$C$3:$D$57,MATCH('balance sheet'!$B6,'Balance Sheet - Data'!$B$3:$B$57,0),MATCH('balance sheet'!H$4,'Balance Sheet - Data'!$C$2:$D$2,0)) -> 868.4 | I6: ='cash Flow'!E56 -> 741.99056 | J6: ='cash Flow'!F56 -> 635.62806 | K6: ='cash Flow'!G56 -> 545.56337 | L6: ='cash Flow'!H56 -> 468.87847 | M6: ='cash Flow'!I56 -> 402.66123
B7: Trade and other receivables | G7: =INDEX('Balance Sheet - Data'!$C$3:$D$57,MATCH('balance sheet'!$B7,'Balance Sheet - Data'!$B$3:$B$57,0),MATCH('balance sheet'!G$4,'Balance Sheet - Data'!$C$2:$D$2,0)) -> 725.7 | H7: =INDEX('Balance Sheet - Data'!$C$3:$D$57,MATCH('balance sheet'!$B7,'Balance Sheet - Data'!$B$3:$B$57,0),MATCH('balance sheet'!H$4,'Balance Sheet - Data'!$C$2:$D$2,0)) -> 774.3 | I7: =H7*(1+'Profit & loss'!E$46) -> 802.06618 | J7: =I7*(1+'Profit & loss'!F$46) -> 818.90345 | K7: =J7*(1+'Profit & loss'!G$46) -> 835.28152 | L7: =K7*(1+'Profit & loss'!H$46) -> 851.98715 | M7: =L7*(1+'Profit & loss'!I$46) -> 869.87888
B8: Prepayments | G8: =INDEX('Balance Sheet - Data'!$C$3:$D$57,MATCH('balance sheet'!$B8,'Balance Sheet - Data'!$B$3:$B$57,0),MATCH('balance sheet'!G$4,'Balance Sheet - Data'!$C$2:$D$2,0)) -> 94 | H8: =INDEX('Balance Sheet - Data'!$C$3:$D$57,MATCH('balance sheet'!$B8,'Balance Sheet - Data'!$B$3:$B$57,0),MATCH('balance sheet'!H$4,'Balance Sheet - Data'!$C$2:$D$2,0)) -> 90.8 | I8: =H8*(1+'Profit & loss'!E$46) -> 94.056063 | J8: =I8*(1+'Profit & loss'!F$46) -> 96.030522 | K8: =J8*(1+'Profit & loss'!G$46) -> 97.951133 | L8: =K8*(1+'Profit & loss'!H$46) -> 99.910155 | M8: =L8*(1+'Profit & loss'!I$46) -> 102.00827
B9: Inventories | G9: =INDEX('Balance Sheet - Data'!$C$3:$D$57,MATCH('balance sheet'!$B9,'Balance Sheet - Data'!$B$3:$B$57,0),MATCH('balance sheet'!G$4,'Balance Sheet - Data'!$C$2:$D$2,0)) -> 158 | H9: =INDEX('Balance Sheet - Data'!$C$3:$D$57,MATCH('balance sheet'!$B9,'Balance Sheet - Data'!$B$3:$B$57,0),MATCH('balance sheet'!H$4,'Balance Sheet - Data'!$C$2:$D$2,0)) -> 151.3 | I9: =H9*(1+'Profit & loss'!E$46) -> 156.72558 | J9: =I9*(1+'Profit & loss'!F$46) -> 160.01562 | K9: =J9*(1+'Profit & loss'!G$46) -> 163.21593 | L9: =K9*(1+'Profit & loss'!H$46) -> 166.48025 | M9: =L9*(1+'Profit & loss'!I$46) -> 169.97633
B10: Assets held for sale | G10: =INDEX('Balance Sheet - Data'!$C$3:$D$57,MATCH('balance sheet'!$B10,'Balance Sheet - Data'!$B$3:$B$57,0),MATCH('balance sheet'!G$4,'Balance Sheet - Data'!$C$2:$D$2,0)) -> 29 | H10: =INDEX('Balance Sheet - Data'!$C$3:$D$57,MATCH('balance sheet'!$B10,'Balance Sheet - Data'!$B$3:$B$57,0),MATCH('balance sheet'!H$4,'Balance Sheet - Data'!$C$2:$D$2,0)) -> 0
B11: Total current assets | G11: =SUM(G6:G10) -> 1899.1 | H11: =SUM(H6:H10) -> 1884.8 | I11: =SUM(I6:I10) -> 1794.8384 | J11: =SUM(J6:J10) -> 1710.5777 | K11: =SUM(K6:K10) -> 1642.012 | L11: =SUM(L6:L10) -> 1587.256 | M11: =SUM(M6:M10) -> 1544.5247
B13: Non-current assets:
B14: Associates and joint ventures | G14: =INDEX('Balance Sheet - Data'!$C$3:$D$57,MATCH('balance sheet'!$B14,'Balance Sheet - Data'!$B$3:$B$57,0),MATCH('balance sheet'!G$4,'Balance Sheet - Data'!$C$2:$D$2,0)) -> 12.9 | H14: =INDEX('Balance Sheet - Data'!$C$3:$D$57,MATCH('balance sheet'!$B14,'Balance Sheet - Data'!$B$3:$B$57,0),MATCH('balance sheet'!H$4,'Balance Sheet - Data'!$C$2:$D$2,0)) -> 14.3 | I14: 14.3 | J14: 14.3 | K14: 14.3 | L14: 14.3 | M14: 14.3
B15: Investments | G15: =INDEX('Balance Sheet - Data'!$C$3:$D$57,MATCH('balance sheet'!$B15,'Balance Sheet - Data'!$B$3:$B$57,0),MATCH('balance sheet'!G$4,'Balance Sheet - Data'!$C$2:$D$2,0)) -> 29.1 | H15: =INDEX('Balance Sheet - Data'!$C$3:$D$57,MATCH('balance sheet'!$B15,'Balance Sheet - Data'!$B$3:$B$57,0),MATCH('balance sheet'!H$4,'Balance Sheet - Data'!$C$2:$D$2,0)) -> 27.6 | I15: 27.6 | J15: 27.6 | K15: 27.6 | L15: 27.6 | M15: 27.6
B16: Trade and other receivables | G16: =INDEX('Balance Sheet - Data'!$C$3:$D$57,MATCH('balance sheet'!$B16,'Balance Sheet - Data'!$B$3:$B$57,0),MATCH('balance sheet'!G$4,'Balance Sheet - Data'!$C$2:$D$2,0)) -> 127.7 | H16: =INDEX('Balance Sheet - Data'!$C$3:$D$57,MATCH('balance sheet'!$B16,'Balance Sheet - Data'!$B$3:$B$57,0),MATCH('balance sheet'!H$4,'Balance Sheet - Data'!$C$2:$D$2,0)) -> 268.9 | I16: 268.9 | J16: 268.9 | K16: 268.9 | L16: 268.9 | M16: 268.9
B17: Vehicles, premises and equipment | G17: =INDEX('Balance Sheet - Data'!$C$3:$D$57,MATCH('balance sheet'!$B17,'Balance Sheet - Data'!$B$3:$B$57,0),MATCH('balance sheet'!G$4,'Balance Sheet - Data'!$C$2:$D$2,0)) -> 2129.6 | H17: =INDEX('Balance Sheet - Data'!$C$3:$D$57,MATCH('balance sheet'!$B17,'Balance Sheet - Data'!$B$3:$B$57,0),MATCH('balance sheet'!H$4,'Balance Sheet - Data'!$C$2:$D$2,0)) -> 2339.3 | I17: ='Fixed assets schedule'!E6 -> 2533.1289 | J17: ='Fixed assets schedule'!F6 -> 2705.6379 | K17: ='Fixed assets schedule'!G6 -> 2860.2214 | L17: ='Fixed assets schedule'!H6 -> 3000.2707 | M17: ='Fixed assets schedule'!I6 -> 3129.2292
B18: Intangible assets | G18: =INDEX('Balance Sheet - Data'!$C$3:$D$57,MATCH('balance sheet'!$B18,'Balance Sheet - Data'!$B$3:$B$57,0),MATCH('balance sheet'!G$4,'Balance Sheet - Data'!$C$2:$D$2,0)) -> 557.8 | H18: =INDEX('Balance Sheet - Data'!$C$3:$D$57,MATCH('balance sheet'!$B18,'Balance Sheet - Data'!$B$3:$B$57,0),MATCH('balance sheet'!H$4,'Balance Sheet - Data'!$C$2:$D$2,0)) -> 557.3 | I18: =H18+('Profit & loss'!E32-'Fixed assets schedule'!E5) -> 530.36765 | J18: =I18+('Profit & loss'!F32-'Fixed assets schedule'!F5) -> 502.86992 | K18: =J18+('Profit & loss'!G32-'Fixed assets schedule'!G5) -> 474.82224 | L18: =K18+('Profit & loss'!H32-'Fixed assets schedule'!H5) -> 446.2136 | M18: =L18+('Profit & loss'!I32-'Fixed assets schedule'!I5) -> 417.00419
B19: Goodwill | G19: =INDEX('Balance Sheet - Data'!$C$3:$D$57,MATCH('balance sheet'!$B19,'Balance Sheet - Data'!$B$3:$B$57,0),MATCH('balance sheet'!G$4,'Balance Sheet - Data'!$C$2:$D$2,0)) -> 955.5 | H19: =INDEX('Balance Sheet - Data'!$C$3:$D$57,MATCH('balance sheet'!$B19,'Balance Sheet - Data'!$B$3:$B$57,0),MATCH('balance sheet'!H$4,'Balance Sheet - Data'!$C$2:$D$2,0)) -> 977.1 | I19: 977.1 | J19: 977.1 | K19: 977.1 | L19: 977.1 | M19: 977.1
B20: Deferred tax assets | G20: =INDEX('Balance Sheet - Data'!$C$3:$D$57,MATCH('balance sheet'!$B20,'Balance Sheet - Data'!$B$3:$B$57,0),MATCH('balance sheet'!G$4,'Balance Sheet - Data'!$C$2:$D$2,0)) -> 69.2 | H20: =INDEX('Balance Sheet - Data'!$C$3:$D$57,MATCH('balance sheet'!$B20,'Balance Sheet - Data'!$B$3:$B$57,0),MATCH('balance sheet'!H$4,'Balance Sheet - Data'!$C$2:$D$2,0)) -> 69.6 | I20: 69.6 | J20: 69.6 | K20: 69.6 | L20: 69.6 | M20: 69.6
B21: Total Non-current Assets | G21: =SUM(G14:G20) -> 3881.8 | H21: =SUM(H14:H20) -> 4254.1 | I21: =SUM(I14:I20) -> 4420.9965 | J21: =SUM(J14:J20) -> 4566.0078 | K21: =SUM(K14:K20) -> 4692.5436 | L21: =SUM(L14:L20) -> 4803.9843 | M21: =SUM(M14:M20) -> 4903.7334
B23: Total assets | G23: =SUM(G21,G11) -> 5780.9 | H23: =SUM(H21,H11) -> 6138.9 | I23: =SUM(I21,I11) -> 6215.8349 | J23: =SUM(J21,J11) -> 6276.5855 | K23: =SUM(K21,K11) -> 6334.5556 | L23: =SUM(L21,L11) -> 6391.2404 | M23: =SUM(M21,M11) -> 6448.2581
B26: Current liabilities
B27: Borrowings | G27: =INDEX('Balance Sheet - Data'!$C$3:$D$57,MATCH('balance sheet'!$B27,'Balance Sheet - Data'!$B$3:$B$57,0),MATCH('balance sheet'!G$4,'Balance Sheet - Data'!$C$2:$D$2,0)) -> 590.5 | H27: =INDEX('Balance Sheet - Data'!$C$3:$D$57,MATCH('balance sheet'!$B27,'Balance Sheet - Data'!$B$3:$B$57,0),MATCH('balance sheet'!H$4,'Balance Sheet - Data'!$C$2:$D$2,0)) -> 387.4 | I27: 387.4 | J27: 387.4 | K27: 387.4 | L27: 387.4 | M27: 387.4
B28: Lease liabilities from financial institutions | G28: =INDEX('Balance Sheet - Data'!$C$3:$D$57,MATCH('balance sheet'!$B28,'Balance Sheet - Data'!$B$3:$B$57,0),MATCH('balance sheet'!G$4,'Balance Sheet - Data'!$C$2:$D$2,0)) -> 4.7 | H28: =INDEX('Balance Sheet - Data'!$C$3:$D$57,MATCH('balance sheet'!$B28,'Balance Sheet - Data'!$B$3:$B$57,0),MATCH('balance sheet'!H$4,'Balance Sheet - Data'!$C$2:$D$2,0)) -> 5.3 | I28: 5.3 | J28: 5.3 | K28: 5.3 | L28: 5.3 | M28: 5.3
B29: Lease liabilities | G29: =INDEX('Balance Sheet - Data'!$C$3:$D$57,MATCH('balance sheet'!$B29,'Balance Sheet - Data'!$B$3:$B$57,0),MATCH('balance sheet'!G$4,'Balance Sheet - Data'!$C$2:$D$2,0)) -> 66.1 | H29: =INDEX('Balance Sheet - Data'!$C$3:$D$57,MATCH('balance sheet'!$B29,'Balance Sheet - Data'!$B$3:$B$57,0),MATCH('balance sheet'!H$4,'Balance Sheet - Data'!$C$2:$D$2,0)) -> 60.1 | I29: 60.1 | J29: 60.1 | K29: 60.1 | L29: 60.1 | M29: 60.1
B30: Trade and other payables | G30: =INDEX('Balance Sheet - Data'!$C$3:$D$57,MATCH('balance sheet'!$B30,'Balance Sheet - Data'!$B$3:$B$57,0),MATCH('balance sheet'!G$4,'Balance Sheet - Data'!$C$2:$D$2,0)) -> 1001.1 | H30: =INDEX('Balance Sheet - Data'!$C$3:$D$57,MATCH('balance sheet'!$B30,'Balance Sheet - Data'!$B$3:$B$57,0),MATCH('balance sheet'!H$4,'Balance Sheet - Data'!$C$2:$D$2,0)) -> 954.2 | I30: =H30*(1+'Profit & loss'!E$46) -> 988.41735 | J30: =I30*(1+'Profit & loss'!F$46) -> 1009.1666 | K30: =J30*(1+'Profit & loss'!G$46) -> 1029.3499 | L30: =K30*(1+'Profit & loss'!H$46) -> 1049.9369 | M30: =L30*(1+'Profit & loss'!I$46) -> 1071.9856
B31: Deferred grants | G31: =INDEX('Balance Sheet - Data'!$C$3:$D$57,MATCH('balance sheet'!$B31,'Balance Sheet - Data'!$B$3:$B$57,0),MATCH('balance sheet'!G$4,'Balance Sheet - Data'!$C$2:$D$2,0)) -> 1.1 | H31: =INDEX('Balance Sheet - Data'!$C$3:$D$57,MATCH('balance sheet'!$B31,'Balance Sheet - Data'!$B$3:$B$57,0),MATCH('balance sheet'!H$4,'Balance Sheet - Data'!$C$2:$D$2,0)) -> 0.7 | I31: 0.7 | J31: 0.7 | K31: 0.7 | L31: 0.7 | M31: 0.7
B32: Fuel price equalisation account | G32: =INDEX('Balance Sheet - Data'!$C$3:$D$57,MATCH('balance sheet'!$B32,'Balance Sheet - Data'!$B$3:$B$57,0),MATCH('balance sheet'!G$4,'Balance Sheet - Data'!$C$2:$D$2,0)) -> 19.4 | H32: =INDEX('Balance Sheet - Data'!$C$3:$D$57,MATCH('balance sheet'!$B32,'Balance Sheet - Data'!$B$3:$B$57,0),MATCH('balance sheet'!H$4,'Balance Sheet - Data'!$C$2:$D$2,0)) -> 19.4 | I32: 19.4 | J32: 19.4 | K32: 19.4 | L32: 19.4 | M32: 19.4
B33: Provision for accident claims | G33: =INDEX('Balance Sheet - Data'!$C$3:$D$57,MATCH('balance sheet'!$B33,'Balance Sheet - Data'!$B$3:$B$57,0),MATCH('balance sheet'!G$4,'Balance Sheet - Data'!$C$2:$D$2,0)) -> 45 | H33: =INDEX('Balance Sheet - Data'!$C$3:$D$57,MATCH('balance sheet'!$B33,'Balance Sheet - Data'!$B$3:$B$57,0),MATCH('balance sheet'!H$4,'Balance Sheet - Data'!$C$2:$D$2,0)) -> 50 | I33: 50 | J33: 50 | K33: 50 | L33: 50 | M33: 50
B34: Income tax payable | G34: =INDEX('Balance Sheet - Data'!$C$3:$D$57,MATCH('balance sheet'!$B34,'Balance Sheet - Data'!$B$3:$B$57,0),MATCH('balance sheet'!G$4,'Balance Sheet - Data'!$C$2:$D$2,0)) -> 72.8 | H34: =INDEX('Balance Sheet - Data'!$C$3:$D$57,MATCH('balance sheet'!$B34,'Balance Sheet - Data'!$B$3:$B$57,0),MATCH('balance sheet'!H$4,'Balance Sheet - Data'!$C$2:$D$2,0)) -> 60 | I34: 60 | J34: 60 | K34: 60 | L34: 60 | M34: 60
B35: Total current liabilities | G35: =SUM(G27:G34) -> 1800.7 | H35: =SUM(H27:H34) -> 1537.1 | I35: =SUM(I27:I34) -> 1571.3173 | J35: =SUM(J27:J34) -> 1592.0666 | K35: =SUM(K27:K34) -> 1612.2499 | L35: =SUM(L27:L34) -> 1632.8369 | M35: =SUM(M27:M34) -> 1654.8856
B37: Non-current liabilities
B38: Borrowings | G38: =INDEX('Balance Sheet - Data'!$C$3:$D$57,MATCH('balance sheet'!$B38,'Balance Sheet - Data'!$B$3:$B$57,0),MATCH('balance sheet'!G$4,'Balance Sheet - Data'!$C$2:$D$2,0)) -> 491.1 | H38: =INDEX('Balance Sheet - Data'!$C$3:$D$57,MATCH('balance sheet'!$B$38,'Balance Sheet - Data'!$B$3:$B$57,0),MATCH('balance sheet'!$H$4,'Balance Sheet - Data'!$C$2:$D$2,0)) -> 1184.8 | I38: =INDEX('Balance Sheet - Data'!$C$3:$D$57,MATCH('balance sheet'!$B$38,'Balance Sheet - Data'!$B$3:$B$57,0),MATCH('balance sheet'!$H$4,'Balance Sheet - Data'!$C$2:$D$2,0)) -> 1184.8 | J38: =INDEX('Balance Sheet - Data'!$C$3:$D$57,MATCH('balance sheet'!$B$38,'Balance Sheet - Data'!$B$3:$B$57,0),MATCH('balance sheet'!$H$4,'Balance Sheet - Data'!$C$2:$D$2,0)) -> 1184.8 | K38: =INDEX('Balance Sheet - Data'!$C$3:$D$57,MATCH('balance sheet'!$B$38,'Balance Sheet - Data'!$B$3:$B$57,0),MATCH('balance sheet'!$H$4,'Balance Sheet - Data'!$C$2:$D$2,0)) -> 1184.8 | L38: =INDEX('Balance Sheet - Data'!$C$3:$D$57,MATCH('balance sheet'!$B$38,'Balance Sheet - Data'!$B$3:$B$57,0),MATCH('balance sheet'!$H$4,'Balance Sheet - Data'!$C$2:$D$2,0)) -> 1184.8 | M38: =INDEX('Balance Sheet - Data'!$C$3:$D$57,MATCH('balance sheet'!$B$38,'Balance Sheet - Data'!$B$3:$B$57,0),MATCH('balance sheet'!$H$4,'Balance Sheet - Data'!$C$2:$D$2,0)) -> 1184.8
B39: Lease liabilities from financial institutions | G39: =INDEX('Balance Sheet - Data'!$C$3:$D$57,MATCH('balance sheet'!$B39,'Balance Sheet - Data'!$B$3:$B$57,0),MATCH('balance sheet'!G$4,'Balance Sheet - Data'!$C$2:$D$2,0)) -> 24.3 | H39: =INDEX('Balance Sheet - Data'!$C$3:$D$57,MATCH('balance sheet'!$B39,'Balance Sheet - Data'!$B$3:$B$57,0),MATCH('balance sheet'!H$4,'Balance Sheet - Data'!$C$2:$D$2,0)) -> 21 | I39: 21 | J39: 21 | K39: 21 | L39: 21 | M39: 21
B40: Lease liabilities | G40: =INDEX('Balance Sheet - Data'!$C$3:$D$57,MATCH('balance sheet'!$B40,'Balance Sheet - Data'!$B$3:$B$57,0),MATCH('balance sheet'!G$4,'Balance Sheet - Data'!$C$2:$D$2,0)) -> 177.9 | H40: =INDEX('Balance Sheet - Data'!$C$3:$D$57,MATCH('balance sheet'!$B40,'Balance Sheet - Data'!$B$3:$B$57,0),MATCH('balance sheet'!H$4,'Balance Sheet - Data'!$C$2:$D$2,0)) -> 162.9 | I40: 162.9 | J40: 162.9 | K40: 162.9 | L40: 162.9 | M40: 162.9
